[2023-01-27T04:58:18.700+0000] {taskinstance.py:1083} INFO - Dependencies all met for <TaskInstance: fhv_taxi_data_dag_v1.upload_to_gcs scheduled__2019-01-01T00:00:00+00:00 [queued]>
[2023-01-27T04:58:18.710+0000] {taskinstance.py:1083} INFO - Dependencies all met for <TaskInstance: fhv_taxi_data_dag_v1.upload_to_gcs scheduled__2019-01-01T00:00:00+00:00 [queued]>
[2023-01-27T04:58:18.710+0000] {taskinstance.py:1279} INFO - 
--------------------------------------------------------------------------------
[2023-01-27T04:58:18.711+0000] {taskinstance.py:1280} INFO - Starting attempt 1 of 1
[2023-01-27T04:58:18.711+0000] {taskinstance.py:1281} INFO - 
--------------------------------------------------------------------------------
[2023-01-27T04:58:18.730+0000] {taskinstance.py:1300} INFO - Executing <Task(_PythonDecoratedOperator): upload_to_gcs> on 2019-01-01 00:00:00+00:00
[2023-01-27T04:58:18.739+0000] {standard_task_runner.py:55} INFO - Started process 7169 to run task
[2023-01-27T04:58:18.742+0000] {standard_task_runner.py:82} INFO - Running: ['***', 'tasks', 'run', 'fhv_taxi_data_dag_v1', 'upload_to_gcs', 'scheduled__2019-01-01T00:00:00+00:00', '--job-id', '5741', '--raw', '--subdir', 'DAGS_FOLDER/data_ingestion_gcs_dag_v1_fhv.py', '--cfg-path', '/tmp/tmp0hf7eeus']
[2023-01-27T04:58:18.743+0000] {standard_task_runner.py:83} INFO - Job 5741: Subtask upload_to_gcs
[2023-01-27T04:58:18.812+0000] {task_command.py:388} INFO - Running <TaskInstance: fhv_taxi_data_dag_v1.upload_to_gcs scheduled__2019-01-01T00:00:00+00:00 [running]> on host 8bc22b99c76b
[2023-01-27T04:58:18.900+0000] {taskinstance.py:1509} INFO - Exporting the following env vars:
AIRFLOW_CTX_DAG_OWNER=***
AIRFLOW_CTX_DAG_ID=fhv_taxi_data_dag_v1
AIRFLOW_CTX_TASK_ID=upload_to_gcs
AIRFLOW_CTX_EXECUTION_DATE=2019-01-01T00:00:00+00:00
AIRFLOW_CTX_TRY_NUMBER=1
AIRFLOW_CTX_DAG_RUN_ID=scheduled__2019-01-01T00:00:00+00:00
[2023-01-27T04:59:19.428+0000] {taskinstance.py:1768} ERROR - Task failed with exception
Traceback (most recent call last):
  File "/home/airflow/.local/lib/python3.7/site-packages/urllib3/connectionpool.py", line 710, in urlopen
    chunked=chunked,
  File "/home/airflow/.local/lib/python3.7/site-packages/urllib3/connectionpool.py", line 398, in _make_request
    conn.request(method, url, **httplib_request_kw)
  File "/home/airflow/.local/lib/python3.7/site-packages/urllib3/connection.py", line 239, in request
    super(HTTPConnection, self).request(method, url, body=body, headers=headers)
  File "/usr/local/lib/python3.7/http/client.py", line 1281, in request
    self._send_request(method, url, body, headers, encode_chunked)
  File "/usr/local/lib/python3.7/http/client.py", line 1327, in _send_request
    self.endheaders(body, encode_chunked=encode_chunked)
  File "/usr/local/lib/python3.7/http/client.py", line 1276, in endheaders
    self._send_output(message_body, encode_chunked=encode_chunked)
  File "/usr/local/lib/python3.7/http/client.py", line 1075, in _send_output
    self.send(chunk)
  File "/usr/local/lib/python3.7/http/client.py", line 997, in send
    self.sock.sendall(data)
  File "/usr/local/lib/python3.7/ssl.py", line 1034, in sendall
    v = self.send(byte_view[count:])
  File "/usr/local/lib/python3.7/ssl.py", line 1003, in send
    return self._sslobj.write(data)
socket.timeout: The write operation timed out

During handling of the above exception, another exception occurred:

Traceback (most recent call last):
  File "/home/airflow/.local/lib/python3.7/site-packages/requests/adapters.py", line 499, in send
    timeout=timeout,
  File "/home/airflow/.local/lib/python3.7/site-packages/urllib3/connectionpool.py", line 788, in urlopen
    method, url, error=e, _pool=self, _stacktrace=sys.exc_info()[2]
  File "/home/airflow/.local/lib/python3.7/site-packages/urllib3/util/retry.py", line 550, in increment
    raise six.reraise(type(error), error, _stacktrace)
  File "/home/airflow/.local/lib/python3.7/site-packages/urllib3/packages/six.py", line 769, in reraise
    raise value.with_traceback(tb)
  File "/home/airflow/.local/lib/python3.7/site-packages/urllib3/connectionpool.py", line 710, in urlopen
    chunked=chunked,
  File "/home/airflow/.local/lib/python3.7/site-packages/urllib3/connectionpool.py", line 398, in _make_request
    conn.request(method, url, **httplib_request_kw)
  File "/home/airflow/.local/lib/python3.7/site-packages/urllib3/connection.py", line 239, in request
    super(HTTPConnection, self).request(method, url, body=body, headers=headers)
  File "/usr/local/lib/python3.7/http/client.py", line 1281, in request
    self._send_request(method, url, body, headers, encode_chunked)
  File "/usr/local/lib/python3.7/http/client.py", line 1327, in _send_request
    self.endheaders(body, encode_chunked=encode_chunked)
  File "/usr/local/lib/python3.7/http/client.py", line 1276, in endheaders
    self._send_output(message_body, encode_chunked=encode_chunked)
  File "/usr/local/lib/python3.7/http/client.py", line 1075, in _send_output
    self.send(chunk)
  File "/usr/local/lib/python3.7/http/client.py", line 997, in send
    self.sock.sendall(data)
  File "/usr/local/lib/python3.7/ssl.py", line 1034, in sendall
    v = self.send(byte_view[count:])
  File "/usr/local/lib/python3.7/ssl.py", line 1003, in send
    return self._sslobj.write(data)
urllib3.exceptions.ProtocolError: ('Connection aborted.', timeout('The write operation timed out'))

During handling of the above exception, another exception occurred:

Traceback (most recent call last):
  File "/home/airflow/.local/lib/python3.7/site-packages/airflow/decorators/base.py", line 217, in execute
    return_value = super().execute(context)
  File "/home/airflow/.local/lib/python3.7/site-packages/airflow/operators/python.py", line 175, in execute
    return_value = self.execute_callable()
  File "/home/airflow/.local/lib/python3.7/site-packages/airflow/operators/python.py", line 192, in execute_callable
    return self.python_callable(*self.op_args, **self.op_kwargs)
  File "/opt/airflow/dags/data_ingestion_gcs_dag_v1_fhv.py", line 72, in upload_to_gcs
    blob.upload_from_filename(f"{path_to_local_home}/{local_file}")
  File "/home/airflow/.local/lib/python3.7/site-packages/google/cloud/storage/blob.py", line 2696, in upload_from_filename
    retry=retry,
  File "/home/airflow/.local/lib/python3.7/site-packages/google/cloud/storage/blob.py", line 2552, in upload_from_file
    retry=retry,
  File "/home/airflow/.local/lib/python3.7/site-packages/google/cloud/storage/blob.py", line 2383, in _do_upload
    retry=retry,
  File "/home/airflow/.local/lib/python3.7/site-packages/google/cloud/storage/blob.py", line 2214, in _do_resumable_upload
    response = upload.transmit_next_chunk(transport, timeout=timeout)
  File "/home/airflow/.local/lib/python3.7/site-packages/google/resumable_media/requests/upload.py", line 516, in transmit_next_chunk
    retriable_request, self._get_status_code, self._retry_strategy
  File "/home/airflow/.local/lib/python3.7/site-packages/google/resumable_media/requests/_request_helpers.py", line 171, in wait_and_retry
    raise error
  File "/home/airflow/.local/lib/python3.7/site-packages/google/resumable_media/requests/_request_helpers.py", line 148, in wait_and_retry
    response = func()
  File "/home/airflow/.local/lib/python3.7/site-packages/google/resumable_media/requests/upload.py", line 508, in retriable_request
    method, url, data=payload, headers=headers, timeout=timeout
  File "/home/airflow/.local/lib/python3.7/site-packages/google/auth/transport/requests.py", line 555, in request
    **kwargs
  File "/home/airflow/.local/lib/python3.7/site-packages/requests/sessions.py", line 587, in request
    resp = self.send(prep, **send_kwargs)
  File "/home/airflow/.local/lib/python3.7/site-packages/requests/sessions.py", line 701, in send
    r = adapter.send(request, **kwargs)
  File "/home/airflow/.local/lib/python3.7/site-packages/requests/adapters.py", line 547, in send
    raise ConnectionError(err, request=request)
requests.exceptions.ConnectionError: ('Connection aborted.', timeout('The write operation timed out'))
[2023-01-27T04:59:19.439+0000] {taskinstance.py:1323} INFO - Marking task as FAILED. dag_id=fhv_taxi_data_dag_v1, task_id=upload_to_gcs, execution_date=20190101T000000, start_date=20230127T045818, end_date=20230127T045919
[2023-01-27T04:59:19.450+0000] {standard_task_runner.py:105} ERROR - Failed to execute job 5741 for task upload_to_gcs (('Connection aborted.', timeout('The write operation timed out')); 7169)
[2023-01-27T04:59:19.469+0000] {local_task_job.py:208} INFO - Task exited with return code 1
[2023-01-27T04:59:19.526+0000] {taskinstance.py:2578} INFO - 0 downstream tasks scheduled from follow-on schedule check
